Workbook
Name ExternalData_1: Charges!$A$1:$F$2
Name ExternalData_1: Details!$A$1:$H$2
Name ExternalData_1: Invoices!$B$1:$AJ$2
Name ExternalData_1: LookupData!$A$1:$AI$2
Name ExternalData_1: 'More fields'!$A$1:$BC$2

Sheet Query
A1: Invoice database - live query
A2: Type a filter (or leave everything empty for all invoices): the sheets Invoices and Charges are filled from the database. They also refresh by themselves every 1 minute(s); Data > Refresh All does it at once.
A4: Filter | B4: Value | H4: sent to the database
A5: Invoice number contains | C5: part of the number, e.g. AMD | H5: ="%"&TRIM(B5)&"%" -> %%
A6: Vendor name contains | C6: part of the name, e.g. dachser | H6: ="%"&TRIM(B6)&"%" -> %%
A7: Invoice date from | C7: a date; empty = no lower limit | H7: =IF(ISNUMBER(B7),YEAR(B7)&"-"&RIGHT("0"&MONTH(B7),2)&"-"&RIGHT("0"&DAY(B7),2),"1900-01-01") -> 1900-01-01
A8: Invoice date to | C8: a date; empty = no upper limit | H8: =IF(ISNUMBER(B8),YEAR(B8)&"-"&RIGHT("0"&MONTH(B8),2)&"-"&RIGHT("0"&DAY(B8),2),"2999-12-31") -> 2999-12-31
A9: Review status | B9: All | C9: All, PENDING, IN_REVIEW, APPROVED, REJECTED, REPROCESSED | H9: =IF(OR(TRIM(B9)="",UPPER(TRIM(B9))="ALL"),"%",UPPER(TRIM(B9))) -> %
A11: Invoices returned | B11: =MAX(0,COUNTA(Invoices!B:B)-1) -> 0
A12: Charge lines returned | B12: =MAX(0,COUNTA(Charges!A:A)-1) -> 0
A13: Charges before GST (INR) | B13: =SUM(Charges!E:E) -> 0
A15: First use: the data source NEON_INVOICE_PG must exist on this computer (see docs/EXCEL_LIVE_QUERY.md). Excel asks for the database password unless it is saved in the data source.
A16: Details for particular invoices: type the invoice numbers in column A of the sheet Lookup; the other columns fill in by themselves, and the sheet Details lists their other details (due date, PO number, parties, ports, totals, bank ...). The sheet More fields has those details as columns for every invoice that matches the filters.

Sheet Lookup
A1: =IF(LEN($AN$1)>5760,"TOO MANY NUMBERS: the last ones are not looked up","Invoice No (type here)") -> Invoice No (type here) | B1: Invoice Date | C1: Container Number | D1: MAWB No | E1: HAWB No | F1: Vendor Name | G1: Bill of Lading / HBL | H1: WEIGHT | I1: Sea Freight | J1: Air Freight | K1: Terminal Handling Charges | L1: Airway WayBill Charges | M1: BL Charges | N1: ENS Charges | O1: Seal Charges | P1: VGM | Q1: EDI Fees | R1: DAP Charges | S1: Other Charges | T1: AMS CHARGES | U1: Handlign Charges | V1: Pre Carriage Haulage | W1: Ex Rate | X1: Misc | Y1: Transportation | Z1: Warehouse charges Port | AA1: Examination charges | AB1: Fuel Charges | AC1: Cargo Screening | AD1: Agency Charges | AE1: Shipping bill charges | AF1: Review status | AG1: Extraction status | AH1: Last updated | AI1: Evidence | AN1: ="~none~|"&AM201 -> ~none~| | AO1: =IF(MID($AN$1,1,240)="","|",MID($AN$1,1,240)) -> ~none~|
B2: =IF($AK2="","",IF($AK2=0,"not in the database",IF(INDEX(LookupData!B:B,$AK2)="","",INDEX(LookupData!B:B,$AK2)))) | C2: =IF($AK2="","",IF($AK2=0,"",IF(INDEX(LookupData!C:C,$AK2)="","",INDEX(LookupData!C:C,$AK2)))) | D2: =IF($AK2="","",IF($AK2=0,"",IF(INDEX(LookupData!D:D,$AK2)="","",INDEX(LookupData!D:D,$AK2)))) | E2: =IF($AK2="","",IF($AK2=0,"",IF(INDEX(LookupData!E:E,$AK2)="","",INDEX(LookupData!E:E,$AK2)))) | F2: =IF($AK2="","",IF($AK2=0,"",IF(INDEX(LookupData!F:F,$AK2)="","",INDEX(LookupData!F:F,$AK2)))) | G2: =IF($AK2="","",IF($AK2=0,"",IF(INDEX(LookupData!G:G,$AK2)="","",INDEX(LookupData!G:G,$AK2)))) | H2: =IF($AK2="","",IF($AK2=0,"",IF(INDEX(LookupData!H:H,$AK2)="","",INDEX(LookupData!H:H,$AK2)))) | I2: =IF($AK2="","",IF($AK2=0,"",IF(INDEX(LookupData!I:I,$AK2)="","",INDEX(LookupData!I:I,$AK2)))) | J2: =IF($AK2="","",IF($AK2=0,"",IF(INDEX(LookupData!J:J,$AK2)="","",INDEX(LookupData!J:J,$AK2)))) | K2: =IF($AK2="","",IF($AK2=0,"",IF(INDEX(LookupData!K:K,$AK2)="","",INDEX(LookupData!K:K,$AK2)))) | L2: =IF($AK2="","",IF($AK2=0,"",IF(INDEX(LookupData!L:L,$AK2)="","",INDEX(LookupData!L:L,$AK2)))) | M2: =IF($AK2="","",IF($AK2=0,"",IF(INDEX(LookupData!M:M,$AK2)="","",INDEX(LookupData!M:M,$AK2)))) | N2: =IF($AK2="","",IF($AK2=0,"",IF(INDEX(LookupData!N:N,$AK2)="","",INDEX(LookupData!N:N,$AK2)))) | O2: =IF($AK2="","",IF($AK2=0,"",IF(INDEX(LookupData!O:O,$AK2)="","",INDEX(LookupData!O:O,$AK2)))) | P2: =IF($AK2="","",IF($AK2=0,"",IF(INDEX(LookupData!P:P,$AK2)="","",INDEX(LookupData!P:P,$AK2)))) | Q2: =IF($AK2="","",IF($AK2=0,"",IF(INDEX(LookupData!Q:Q,$AK2)="","",INDEX(LookupData!Q:Q,$AK2)))) | R2: =IF($AK2="","",IF($AK2=0,"",IF(INDEX(LookupData!R:R,$AK2)="","",INDEX(LookupData!R:R,$AK2)))) | S2: =IF($AK2="","",IF($AK2=0,"",IF(INDEX(LookupData!S:S,$AK2)="","",INDEX(LookupData!S:S,$AK2)))) | T2: =IF($AK2="","",IF($AK2=0,"",IF(INDEX(LookupData!T:T,$AK2)="","",INDEX(LookupData!T:T,$AK2)))) | U2: =IF($AK2="","",IF($AK2=0,"",IF(INDEX(LookupData!U:U,$AK2)="","",INDEX(LookupData!U:U,$AK2)))) | V2: =IF($AK2="","",IF($AK2=0,"",IF(INDEX(LookupData!V:V,$AK2)="","",INDEX(LookupData!V:V,$AK2)))) | W2: =IF($AK2="","",IF($AK2=0,"",IF(INDEX(LookupData!W:W,$AK2)="","",INDEX(LookupData!W:W,$AK2)))) | X2: =IF($AK2="","",IF($AK2=0,"",IF(INDEX(LookupData!X:X,$AK2)="","",INDEX(LookupData!X:X,$AK2)))) | Y2: =IF($AK2="","",IF($AK2=0,"",IF(INDEX(LookupData!Y:Y,$AK2)="","",INDEX(LookupData!Y:Y,$AK2)))) | Z2: =IF($AK2="","",IF($AK2=0,"",IF(INDEX(LookupData!Z:Z,$AK2)="","",INDEX(LookupData!Z:Z,$AK2)))) | AA2: =IF($AK2="","",IF($AK2=0,"",IF(INDEX(LookupData!AA:AA,$AK2)="","",INDEX(LookupData!AA:AA,$AK2)))) | AB2: =IF($AK2="","",IF($AK2=0,"",IF(INDEX(LookupData!AB:AB,$AK2)="","",INDEX(LookupData!AB:AB,$AK2)))) | AC2: =IF($AK2="","",IF($AK2=0,"",IF(INDEX(LookupData!AC:AC,$AK2)="","",INDEX(LookupData!AC:AC,$AK2)))) | AD2: =IF($AK2="","",IF($AK2=0,"",IF(INDEX(LookupData!AD:AD,$AK2)="","",INDEX(LookupData!AD:AD,$AK2)))) | AE2: =IF($AK2="","",IF($AK2=0,"",IF(INDEX(LookupData!AE:AE,$AK2)="","",INDEX(LookupData!AE:AE,$AK2)))) | AF2: =IF($AK2="","",IF($AK2=0,"",IF(INDEX(LookupData!AF:AF,$AK2)="","",INDEX(LookupData!AF:AF,$AK2)))) | AG2: =IF($AK2="","",IF($AK2=0,"",IF(INDEX(LookupData!AG:AG,$AK2)="","",INDEX(LookupData!AG:AG,$AK2)))) | AH2: =IF($AK2="","",IF($AK2=0,"",IF(INDEX(LookupData!AH:AH,$AK2)="","",INDEX(LookupData!AH:AH,$AK2)))) | AI2: =IF($AK2="","",IF($AK2=0,"",IF(INDEX(LookupData!AI:AI,$AK2)="","",HYPERLINK(INDEX(LookupData!AI:AI,$AK2),"Open")))) | AK2: =IF(AL2="","",IFERROR(MATCH(AL2,LookupData!$A:$A,0),0)) | AL2: =IF(TRIM($A2)="","",UPPER(TRIM($A2))) | AM2: =AL2 | AO2: =IF(MID($AN$1,241,240)="","|",MID($AN$1,241,240)) -> |
B3: =IF($AK3="","",IF($AK3=0,"not in the database",IF(INDEX(LookupData!B:B,$AK3)="","",INDEX(LookupData!B:B,$AK3)))) | C3: =IF($AK3="","",IF($AK3=0,"",IF(INDEX(LookupData!C:C,$AK3)="","",INDEX(LookupData!C:C,$AK3)))) | D3: =IF($AK3="","",IF($AK3=0,"",IF(INDEX(LookupData!D:D,$AK3)="","",INDEX(LookupData!D:D,$AK3)))) | E3: =IF($AK3="","",IF($AK3=0,"",IF(INDEX(LookupData!E:E,$AK3)="","",INDEX(LookupData!E:E,$AK3)))) | F3: =IF($AK3="","",IF($AK3=0,"",IF(INDEX(LookupData!F:F,$AK3)="","",INDEX(LookupData!F:F,$AK3)))) | G3: =IF($AK3="","",IF($AK3=0,"",IF(INDEX(LookupData!G:G,$AK3)="","",INDEX(LookupData!G:G,$AK3)))) | H3: =IF($AK3="","",IF($AK3=0,"",IF(INDEX(LookupData!H:H,$AK3)="","",INDEX(LookupData!H:H,$AK3)))) | I3: =IF($AK3="","",IF($AK3=0,"",IF(INDEX(LookupData!I:I,$AK3)="","",INDEX(LookupData!I:I,$AK3)))) | J3: =IF($AK3="","",IF($AK3=0,"",IF(INDEX(LookupData!J:J,$AK3)="","",INDEX(LookupData!J:J,$AK3)))) | K3: =IF($AK3="","",IF($AK3=0,"",IF(INDEX(LookupData!K:K,$AK3)="","",INDEX(LookupData!K:K,$AK3)))) | L3: =IF($AK3="","",IF($AK3=0,"",IF(INDEX(LookupData!L:L,$AK3)="","",INDEX(LookupData!L:L,$AK3)))) | M3: =IF($AK3="","",IF($AK3=0,"",IF(INDEX(LookupData!M:M,$AK3)="","",INDEX(LookupData!M:M,$AK3)))) | N3: =IF($AK3="","",IF($AK3=0,"",IF(INDEX(LookupData!N:N,$AK3)="","",INDEX(LookupData!N:N,$AK3)))) | O3: =IF($AK3="","",IF($AK3=0,"",IF(INDEX(LookupData!O:O,$AK3)="","",INDEX(LookupData!O:O,$AK3)))) | P3: =IF($AK3="","",IF($AK3=0,"",IF(INDEX(LookupData!P:P,$AK3)="","",INDEX(LookupData!P:P,$AK3)))) | Q3: =IF($AK3="","",IF($AK3=0,"",IF(INDEX(LookupData!Q:Q,$AK3)="","",INDEX(LookupData!Q:Q,$AK3)))) | R3: =IF($AK3="","",IF($AK3=0,"",IF(INDEX(LookupData!R:R,$AK3)="","",INDEX(LookupData!R:R,$AK3)))) | S3: =IF($AK3="","",IF($AK3=0,"",IF(INDEX(LookupData!S:S,$AK3)="","",INDEX(LookupData!S:S,$AK3)))) | T3: =IF($AK3="","",IF($AK3=0,"",IF(INDEX(LookupData!T:T,$AK3)="","",INDEX(LookupData!T:T,$AK3)))) | U3: =IF($AK3="","",IF($AK3=0,"",IF(INDEX(LookupData!U:U,$AK3)="","",INDEX(LookupData!U:U,$AK3)))) | V3: =IF($AK3="","",IF($AK3=0,"",IF(INDEX(LookupData!V:V,$AK3)="","",INDEX(LookupData!V:V,$AK3)))) | W3: =IF($AK3="","",IF($AK3=0,"",IF(INDEX(LookupData!W:W,$AK3)="","",INDEX(LookupData!W:W,$AK3)))) | X3: =IF($AK3="","",IF($AK3=0,"",IF(INDEX(LookupData!X:X,$AK3)="","",INDEX(LookupData!X:X,$AK3)))) | Y3: =IF($AK3="","",IF($AK3=0,"",IF(INDEX(LookupData!Y:Y,$AK3)="","",INDEX(LookupData!Y:Y,$AK3)))) | Z3: =IF($AK3="","",IF($AK3=0,"",IF(INDEX(LookupData!Z:Z,$AK3)="","",INDEX(LookupData!Z:Z,$AK3)))) | AA3: =IF($AK3="","",IF($AK3=0,"",IF(INDEX(LookupData!AA:AA,$AK3)="","",INDEX(LookupData!AA:AA,$AK3)))) | AB3: =IF($AK3="","",IF($AK3=0,"",IF(INDEX(LookupData!AB:AB,$AK3)="","",INDEX(LookupData!AB:AB,$AK3)))) | AC3: =IF($AK3="","",IF($AK3=0,"",IF(INDEX(LookupData!AC:AC,$AK3)="","",INDEX(LookupData!AC:AC,$AK3)))) | AD3: =IF($AK3="","",IF($AK3=0,"",IF(INDEX(LookupData!AD:AD,$AK3)="","",INDEX(LookupData!AD:AD,$AK3)))) | AE3: =IF($AK3="","",IF($AK3=0,"",IF(INDEX(LookupData!AE:AE,$AK3)="","",INDEX(LookupData!AE:AE,$AK3)))) | AF3: =IF($AK3="","",IF($AK3=0,"",IF(INDEX(LookupData!AF:AF,$AK3)="","",INDEX(LookupData!AF:AF,$AK3)))) | AG3: =IF($AK3="","",IF($AK3=0,"",IF(INDEX(LookupData!AG:AG,$AK3)="","",INDEX(LookupData!AG:AG,$AK3)))) | AH3: =IF($AK3="","",IF($AK3=0,"",IF(INDEX(LookupData!AH:AH,$AK3)="","",INDEX(LookupData!AH:AH,$AK3)))) | AI3: =IF($AK3="","",IF($AK3=0,"",IF(INDEX(LookupData!AI:AI,$AK3)="","",HYPERLINK(INDEX(LookupData!AI:AI,$AK3),"Open")))) | AK3: =IF(AL3="","",IFERROR(MATCH(AL3,LookupData!$A:$A,0),0)) | AL3: =IF(TRIM($A3)="","",UPPER(TRIM($A3))) | AM3: =IF(AL3="",AM2,IF(AM2="",AL3,AM2&"|"&AL3)) | AO3: =IF(MID($AN$1,481,240)="","|",MID($AN$1,481,240)) -> |
B4: =IF($AK4="","",IF($AK4=0,"not in the database",IF(INDEX(LookupData!B:B,$AK4)="","",INDEX(LookupData!B:B,$AK4)))) | C4: =IF($AK4="","",IF($AK4=0,"",IF(INDEX(LookupData!C:C,$AK4)="","",INDEX(LookupData!C:C,$AK4)))) | D4: =IF($AK4="","",IF($AK4=0,"",IF(INDEX(LookupData!D:D,$AK4)="","",INDEX(LookupData!D:D,$AK4)))) | E4: =IF($AK4="","",IF($AK4=0,"",IF(INDEX(LookupData!E:E,$AK4)="","",INDEX(LookupData!E:E,$AK4)))) | F4: =IF($AK4="","",IF($AK4=0,"",IF(INDEX(LookupData!F:F,$AK4)="","",INDEX(LookupData!F:F,$AK4)))) | G4: =IF($AK4="","",IF($AK4=0,"",IF(INDEX(LookupData!G:G,$AK4)="","",INDEX(LookupData!G:G,$AK4)))) | H4: =IF($AK4="","",IF($AK4=0,"",IF(INDEX(LookupData!H:H,$AK4)="","",INDEX(LookupData!H:H,$AK4)))) | I4: =IF($AK4="","",IF($AK4=0,"",IF(INDEX(LookupData!I:I,$AK4)="","",INDEX(LookupData!I:I,$AK4)))) | J4: =IF($AK4="","",IF($AK4=0,"",IF(INDEX(LookupData!J:J,$AK4)="","",INDEX(LookupData!J:J,$AK4)))) | K4: =IF($AK4="","",IF($AK4=0,"",IF(INDEX(LookupData!K:K,$AK4)="","",INDEX(LookupData!K:K,$AK4)))) | L4: =IF($AK4="","",IF($AK4=0,"",IF(INDEX(LookupData!L:L,$AK4)="","",INDEX(LookupData!L:L,$AK4)))) | M4: =IF($AK4="","",IF($AK4=0,"",IF(INDEX(LookupData!M:M,$AK4)="","",INDEX(LookupData!M:M,$AK4)))) | N4: =IF($AK4="","",IF($AK4=0,"",IF(INDEX(LookupData!N:N,$AK4)="","",INDEX(LookupData!N:N,$AK4)))) | O4: =IF($AK4="","",IF($AK4=0,"",IF(INDEX(LookupData!O:O,$AK4)="","",INDEX(LookupData!O:O,$AK4)))) | P4: =IF($AK4="","",IF($AK4=0,"",IF(INDEX(LookupData!P:P,$AK4)="","",INDEX(LookupData!P:P,$AK4)))) | Q4: =IF($AK4="","",IF($AK4=0,"",IF(INDEX(LookupData!Q:Q,$AK4)="","",INDEX(LookupData!Q:Q,$AK4)))) | R4: =IF($AK4="","",IF($AK4=0,"",IF(INDEX(LookupData!R:R,$AK4)="","",INDEX(LookupData!R:R,$AK4)))) | S4: =IF($AK4="","",IF($AK4=0,"",IF(INDEX(LookupData!S:S,$AK4)="","",INDEX(LookupData!S:S,$AK4)))) | T4: =IF($AK4="","",IF($AK4=0,"",IF(INDEX(LookupData!T:T,$AK4)="","",INDEX(LookupData!T:T,$AK4)))) | U4: =IF($AK4="","",IF($AK4=0,"",IF(INDEX(LookupData!U:U,$AK4)="","",INDEX(LookupData!U:U,$AK4)))) | V4: =IF($AK4="","",IF($AK4=0,"",IF(INDEX(LookupData!V:V,$AK4)="","",INDEX(LookupData!V:V,$AK4)))) | W4: =IF($AK4="","",IF($AK4=0,"",IF(INDEX(LookupData!W:W,$AK4)="","",INDEX(LookupData!W:W,$AK4)))) | X4: =IF($AK4="","",IF($AK4=0,"",IF(INDEX(LookupData!X:X,$AK4)="","",INDEX(LookupData!X:X,$AK4)))) | Y4: =IF($AK4="","",IF($AK4=0,"",IF(INDEX(LookupData!Y:Y,$AK4)="","",INDEX(LookupData!Y:Y,$AK4)))) | Z4: =IF($AK4="","",IF($AK4=0,"",IF(INDEX(LookupData!Z:Z,$AK4)="","",INDEX(LookupData!Z:Z,$AK4)))) | AA4: =IF($AK4="","",IF($AK4=0,"",IF(INDEX(LookupData!AA:AA,$AK4)="","",INDEX(LookupData!AA:AA,$AK4)))) | AB4: =IF($AK4="","",IF($AK4=0,"",IF(INDEX(LookupData!AB:AB,$AK4)="","",INDEX(LookupData!AB:AB,$AK4)))) | AC4: =IF($AK4="","",IF($AK4=0,"",IF(INDEX(LookupData!AC:AC,$AK4)="","",INDEX(LookupData!AC:AC,$AK4)))) | AD4: =IF($AK4="","",IF($AK4=0,"",IF(INDEX(LookupData!AD:AD,$AK4)="","",INDEX(LookupData!AD:AD,$AK4)))) | AE4: =IF($AK4="","",IF($AK4=0,"",IF(INDEX(LookupData!AE:AE,$AK4)="","",INDEX(LookupData!AE:AE,$AK4)))) | AF4: =IF($AK4="","",IF($AK4=0,"",IF(INDEX(LookupData!AF:AF,$AK4)="","",INDEX(LookupData!AF:AF,$AK4)))) | AG4: =IF($AK4="","",IF($AK4=0,"",IF(INDEX(LookupData!AG:AG,$AK4)="","",INDEX(LookupData!AG:AG,$AK4)))) | AH4: =IF($AK4="","",IF($AK4=0,"",IF(INDEX(LookupData!AH:AH,$AK4)="","",INDEX(LookupData!AH:AH,$AK4)))) | AI4: =IF($AK4="","",IF($AK4=0,"",IF(INDEX(LookupData!AI:AI,$AK4)="","",HYPERLINK(INDEX(LookupData!AI:AI,$AK4),"Open")))) | AK4: =IF(AL4="","",IFERROR(MATCH(AL4,LookupData!$A:$A,0),0)) | AL4: =IF(TRIM($A4)="","",UPPER(TRIM($A4))) | AM4: =IF(AL4="",AM3,IF(AM3="",AL4,AM3&"|"&AL4)) | AO4: =IF(MID($AN$1,721,240)="","|",MID($AN$1,721,240)) -> |
B5: =IF($AK5="","",IF($AK5=0,"not in the database",IF(INDEX(LookupData!B:B,$AK5)="","",INDEX(LookupData!B:B,$AK5)))) | C5: =IF($AK5="","",IF($AK5=0,"",IF(INDEX(LookupData!C:C,$AK5)="","",INDEX(LookupData!C:C,$AK5)))) | D5: =IF($AK5="","",IF($AK5=0,"",IF(INDEX(LookupData!D:D,$AK5)="","",INDEX(LookupData!D:D,$AK5)))) | E5: =IF($AK5="","",IF($AK5=0,"",IF(INDEX(LookupData!E:E,$AK5)="","",INDEX(LookupData!E:E,$AK5)))) | F5: =IF($AK5="","",IF($AK5=0,"",IF(INDEX(LookupData!F:F,$AK5)="","",INDEX(LookupData!F:F,$AK5)))) | G5: =IF($AK5="","",IF($AK5=0,"",IF(INDEX(LookupData!G:G,$AK5)="","",INDEX(LookupData!G:G,$AK5)))) | H5: =IF($AK5="","",IF($AK5=0,"",IF(INDEX(LookupData!H:H,$AK5)="","",INDEX(LookupData!H:H,$AK5)))) | I5: =IF($AK5="","",IF($AK5=0,"",IF(INDEX(LookupData!I:I,$AK5)="","",INDEX(LookupData!I:I,$AK5)))) | J5: =IF($AK5="","",IF($AK5=0,"",IF(INDEX(LookupData!J:J,$AK5)="","",INDEX(LookupData!J:J,$AK5)))) | K5: =IF($AK5="","",IF($AK5=0,"",IF(INDEX(LookupData!K:K,$AK5)="","",INDEX(LookupData!K:K,$AK5)))) | L5: =IF($AK5="","",IF($AK5=0,"",IF(INDEX(LookupData!L:L,$AK5)="","",INDEX(LookupData!L:L,$AK5)))) | M5: =IF($AK5="","",IF($AK5=0,"",IF(INDEX(LookupData!M:M,$AK5)="","",INDEX(LookupData!M:M,$AK5)))) | N5: =IF($AK5="","",IF($AK5=0,"",IF(INDEX(LookupData!N:N,$AK5)="","",INDEX(LookupData!N:N,$AK5)))) | O5: =IF($AK5="","",IF($AK5=0,"",IF(INDEX(LookupData!O:O,$AK5)="","",INDEX(LookupData!O:O,$AK5)))) | P5: =IF($AK5="","",IF($AK5=0,"",IF(INDEX(LookupData!P:P,$AK5)="","",INDEX(LookupData!P:P,$AK5)))) | Q5: =IF($AK5="","",IF($AK5=0,"",IF(INDEX(LookupData!Q:Q,$AK5)="","",INDEX(LookupData!Q:Q,$AK5)))) | R5: =IF($AK5="","",IF($AK5=0,"",IF(INDEX(LookupData!R:R,$AK5)="","",INDEX(LookupData!R:R,$AK5)))) | S5: =IF($AK5="","",IF($AK5=0,"",IF(INDEX(LookupData!S:S,$AK5)="","",INDEX(LookupData!S:S,$AK5)))) | T5: =IF($AK5="","",IF($AK5=0,"",IF(INDEX(LookupData!T:T,$AK5)="","",INDEX(LookupData!T:T,$AK5)))) | U5: =IF($AK5="","",IF($AK5=0,"",IF(INDEX(LookupData!U:U,$AK5)="","",INDEX(LookupData!U:U,$AK5)))) | V5: =IF($AK5="","",IF($AK5=0,"",IF(INDEX(LookupData!V:V,$AK5)="","",INDEX(LookupData!V:V,$AK5)))) | W5: =IF($AK5="","",IF($AK5=0,"",IF(INDEX(LookupData!W:W,$AK5)="","",INDEX(LookupData!W:W,$AK5)))) | X5: =IF($AK5="","",IF($AK5=0,"",IF(INDEX(LookupData!X:X,$AK5)="","",INDEX(LookupData!X:X,$AK5)))) | Y5: =IF($AK5="","",IF($AK5=0,"",IF(INDEX(LookupData!Y:Y,$AK5)="","",INDEX(LookupData!Y:Y,$AK5)))) | Z5: =IF($AK5="","",IF($AK5=0,"",IF(INDEX(LookupData!Z:Z,$AK5)="","",INDEX(LookupData!Z:Z,$AK5)))) | AA5: =IF($AK5="","",IF($AK5=0,"",IF(INDEX(LookupData!AA:AA,$AK5)="","",INDEX(LookupData!AA:AA,$AK5)))) | AB5: =IF($AK5="","",IF($AK5=0,"",IF(INDEX(LookupData!AB:AB,$AK5)="","",INDEX(LookupData!AB:AB,$AK5)))) | AC5: =IF($AK5="","",IF($AK5=0,"",IF(INDEX(LookupData!AC:AC,$AK5)="","",INDEX(LookupData!AC:AC,$AK5)))) | AD5: =IF($AK5="","",IF($AK5=0,"",IF(INDEX(LookupData!AD:AD,$AK5)="","",INDEX(LookupData!AD:AD,$AK5)))) | AE5: =IF($AK5="","",IF($AK5=0,"",IF(INDEX(LookupData!AE:AE,$AK5)="","",INDEX(LookupData!AE:AE,$AK5)))) | AF5: =IF($AK5="","",IF($AK5=0,"",IF(INDEX(LookupData!AF:AF,$AK5)="","",INDEX(LookupData!AF:AF,$AK5)))) | AG5: =IF($AK5="","",IF($AK5=0,"",IF(INDEX(LookupData!AG:AG,$AK5)="","",INDEX(LookupData!AG:AG,$AK5)))) | AH5: =IF($AK5="","",IF($AK5=0,"",IF(INDEX(LookupData!AH:AH,$AK5)="","",INDEX(LookupData!AH:AH,$AK5)))) | AI5: =IF($AK5="","",IF($AK5=0,"",IF(INDEX(LookupData!AI:AI,$AK5)="","",HYPERLINK(INDEX(LookupData!AI:AI,$AK5),"Open")))) | AK5: =IF(AL5="","",IFERROR(MATCH(AL5,LookupData!$A:$A,0),0)) | AL5: =IF(TRIM($A5)="","",UPPER(TRIM($A5))) | AM5: =IF(AL5="",AM4,IF(AM4="",AL5,AM4&"|"&AL5)) | AO5: =IF(MID($AN$1,961,240)="","|",MID($AN$1,961,240)) -> |
B6: =IF($AK6="","",IF($AK6=0,"not in the database",IF(INDEX(LookupData!B:B,$AK6)="","",INDEX(LookupData!B:B,$AK6)))) | C6: =IF($AK6="","",IF($AK6=0,"",IF(INDEX(LookupData!C:C,$AK6)="","",INDEX(LookupData!C:C,$AK6)))) | D6: =IF($AK6="","",IF($AK6=0,"",IF(INDEX(LookupData!D:D,$AK6)="","",INDEX(LookupData!D:D,$AK6)))) | E6: =IF($AK6="","",IF($AK6=0,"",IF(INDEX(LookupData!E:E,$AK6)="","",INDEX(LookupData!E:E,$AK6)))) | F6: =IF($AK6="","",IF($AK6=0,"",IF(INDEX(LookupData!F:F,$AK6)="","",INDEX(LookupData!F:F,$AK6)))) | G6: =IF($AK6="","",IF($AK6=0,"",IF(INDEX(LookupData!G:G,$AK6)="","",INDEX(LookupData!G:G,$AK6)))) | H6: =IF($AK6="","",IF($AK6=0,"",IF(INDEX(LookupData!H:H,$AK6)="","",INDEX(LookupData!H:H,$AK6)))) | I6: =IF($AK6="","",IF($AK6=0,"",IF(INDEX(LookupData!I:I,$AK6)="","",INDEX(LookupData!I:I,$AK6)))) | J6: =IF($AK6="","",IF($AK6=0,"",IF(INDEX(LookupData!J:J,$AK6)="","",INDEX(LookupData!J:J,$AK6)))) | K6: =IF($AK6="","",IF($AK6=0,"",IF(INDEX(LookupData!K:K,$AK6)="","",INDEX(LookupData!K:K,$AK6)))) | L6: =IF($AK6="","",IF($AK6=0,"",IF(INDEX(LookupData!L:L,$AK6)="","",INDEX(LookupData!L:L,$AK6)))) | M6: =IF($AK6="","",IF($AK6=0,"",IF(INDEX(LookupData!M:M,$AK6)="","",INDEX(LookupData!M:M,$AK6)))) | N6: =IF($AK6="","",IF($AK6=0,"",IF(INDEX(LookupData!N:N,$AK6)="","",INDEX(LookupData!N:N,$AK6)))) | O6: =IF($AK6="","",IF($AK6=0,"",IF(INDEX(LookupData!O:O,$AK6)="","",INDEX(LookupData!O:O,$AK6)))) | P6: =IF($AK6="","",IF($AK6=0,"",IF(INDEX(LookupData!P:P,$AK6)="","",INDEX(LookupData!P:P,$AK6)))) | Q6: =IF($AK6="","",IF($AK6=0,"",IF(INDEX(LookupData!Q:Q,$AK6)="","",INDEX(LookupData!Q:Q,$AK6)))) | R6: =IF($AK6="","",IF($AK6=0,"",IF(INDEX(LookupData!R:R,$AK6)="","",INDEX(LookupData!R:R,$AK6)))) | S6: =IF($AK6="","",IF($AK6=0,"",IF(INDEX(LookupData!S:S,$AK6)="","",INDEX(LookupData!S:S,$AK6)))) | T6: =IF($AK6="","",IF($AK6=0,"",IF(INDEX(LookupData!T:T,$AK6)="","",INDEX(LookupData!T:T,$AK6)))) | U6: =IF($AK6="","",IF($AK6=0,"",IF(INDEX(LookupData!U:U,$AK6)="","",INDEX(LookupData!U:U,$AK6)))) | V6: =IF($AK6="","",IF($AK6=0,"",IF(INDEX(LookupData!V:V,$AK6)="","",INDEX(LookupData!V:V,$AK6)))) | W6: =IF($AK6="","",IF($AK6=0,"",IF(INDEX(LookupData!W:W,$AK6)="","",INDEX(LookupData!W:W,$AK6)))) | X6: =IF($AK6="","",IF($AK6=0,"",IF(INDEX(LookupData!X:X,$AK6)="","",INDEX(LookupData!X:X,$AK6)))) | Y6: =IF($AK6="","",IF($AK6=0,"",IF(INDEX(LookupData!Y:Y,$AK6)="","",INDEX(LookupData!Y:Y,$AK6)))) | Z6: =IF($AK6="","",IF($AK6=0,"",IF(INDEX(LookupData!Z:Z,$AK6)="","",INDEX(LookupData!Z:Z,$AK6)))) | AA6: =IF($AK6="","",IF($AK6=0,"",IF(INDEX(LookupData!AA:AA,$AK6)="","",INDEX(LookupData!AA:AA,$AK6)))) | AB6: =IF($AK6="","",IF($AK6=0,"",IF(INDEX(LookupData!AB:AB,$AK6)="","",INDEX(LookupData!AB:AB,$AK6)))) | AC6: =IF($AK6="","",IF($AK6=0,"",IF(INDEX(LookupData!AC:AC,$AK6)="","",INDEX(LookupData!AC:AC,$AK6)))) | AD6: =IF($AK6="","",IF($AK6=0,"",IF(INDEX(LookupData!AD:AD,$AK6)="","",INDEX(LookupData!AD:AD,$AK6)))) | AE6: =IF($AK6="","",IF($AK6=0,"",IF(INDEX(LookupData!AE:AE,$AK6)="","",INDEX(LookupData!AE:AE,$AK6)))) | AF6: =IF($AK6="","",IF($AK6=0,"",IF(INDEX(LookupData!AF:AF,$AK6)="","",INDEX(LookupData!AF:AF,$AK6)))) | AG6: =IF($AK6="","",IF($AK6=0,"",IF(INDEX(LookupData!AG:AG,$AK6)="","",INDEX(LookupData!AG:AG,$AK6)))) | AH6: =IF($AK6="","",IF($AK6=0,"",IF(INDEX(LookupData!AH:AH,$AK6)="","",INDEX(LookupData!AH:AH,$AK6)))) | AI6: =IF($AK6="","",IF($AK6=0,"",IF(INDEX(LookupData!AI:AI,$AK6)="","",HYPERLINK(INDEX(LookupData!AI:AI,$AK6),"Open")))) | AK6: =IF(AL6="","",IFERROR(MATCH(AL6,LookupData!$A:$A,0),0)) | AL6: =IF(TRIM($A6)="","",UPPER(TRIM($A6))) | AM6: =IF(AL6="",AM5,IF(AM5="",AL6,AM5&"|"&AL6)) | AO6: =IF(MID($AN$1,1201,240)="","|",MID($AN$1,1201,240)) -> |
B7: =IF($AK7="","",IF($AK7=0,"not in the database",IF(INDEX(LookupData!B:B,$AK7)="","",INDEX(LookupData!B:B,$AK7)))) | C7: =IF($AK7="","",IF($AK7=0,"",IF(INDEX(LookupData!C:C,$AK7)="","",INDEX(LookupData!C:C,$AK7)))) | D7: =IF($AK7="","",IF($AK7=0,"",IF(INDEX(LookupData!D:D,$AK7)="","",INDEX(LookupData!D:D,$AK7)))) | E7: =IF($AK7="","",IF($AK7=0,"",IF(INDEX(LookupData!E:E,$AK7)="","",INDEX(LookupData!E:E,$AK7)))) | F7: =IF($AK7="","",IF($AK7=0,"",IF(INDEX(LookupData!F:F,$AK7)="","",INDEX(LookupData!F:F,$AK7)))) | G7: =IF($AK7="","",IF($AK7=0,"",IF(INDEX(LookupData!G:G,$AK7)="","",INDEX(LookupData!G:G,$AK7)))) | H7: =IF($AK7="","",IF($AK7=0,"",IF(INDEX(LookupData!H:H,$AK7)="","",INDEX(LookupData!H:H,$AK7)))) | I7: =IF($AK7="","",IF($AK7=0,"",IF(INDEX(LookupData!I:I,$AK7)="","",INDEX(LookupData!I:I,$AK7)))) | J7: =IF($AK7="","",IF($AK7=0,"",IF(INDEX(LookupData!J:J,$AK7)="","",INDEX(LookupData!J:J,$AK7)))) | K7: =IF($AK7="","",IF($AK7=0,"",IF(INDEX(LookupData!K:K,$AK7)="","",INDEX(LookupData!K:K,$AK7)))) | L7: =IF($AK7="","",IF($AK7=0,"",IF(INDEX(LookupData!L:L,$AK7)="","",INDEX(LookupData!L:L,$AK7)))) | M7: =IF($AK7="","",IF($AK7=0,"",IF(INDEX(LookupData!M:M,$AK7)="","",INDEX(LookupData!M:M,$AK7)))) | N7: =IF($AK7="","",IF($AK7=0,"",IF(INDEX(LookupData!N:N,$AK7)="","",INDEX(LookupData!N:N,$AK7)))) | O7: =IF($AK7="","",IF($AK7=0,"",IF(INDEX(LookupData!O:O,$AK7)="","",INDEX(LookupData!O:O,$AK7)))) | P7: =IF($AK7="","",IF($AK7=0,"",IF(INDEX(LookupData!P:P,$AK7)="","",INDEX(LookupData!P:P,$AK7)))) | Q7: =IF($AK7="","",IF($AK7=0,"",IF(INDEX(LookupData!Q:Q,$AK7)="","",INDEX(LookupData!Q:Q,$AK7)))) | R7: =IF($AK7="","",IF($AK7=0,"",IF(INDEX(LookupData!R:R,$AK7)="","",INDEX(LookupData!R:R,$AK7)))) | S7: =IF($AK7="","",IF($AK7=0,"",IF(INDEX(LookupData!S:S,$AK7)="","",INDEX(LookupData!S:S,$AK7)))) | T7: =IF($AK7="","",IF($AK7=0,"",IF(INDEX(LookupData!T:T,$AK7)="","",INDEX(LookupData!T:T,$AK7)))) | U7: =IF($AK7="","",IF($AK7=0,"",IF(INDEX(LookupData!U:U,$AK7)="","",INDEX(LookupData!U:U,$AK7)))) | V7: =IF($AK7="","",IF($AK7=0,"",IF(INDEX(LookupData!V:V,$AK7)="","",INDEX(LookupData!V:V,$AK7)))) | W7: =IF($AK7="","",IF($AK7=0,"",IF(INDEX(LookupData!W:W,$AK7)="","",INDEX(LookupData!W:W,$AK7)))) | X7: =IF($AK7="","",IF($AK7=0,"",IF(INDEX(LookupData!X:X,$AK7)="","",INDEX(LookupData!X:X,$AK7)))) | Y7: =IF($AK7="","",IF($AK7=0,"",IF(INDEX(LookupData!Y:Y,$AK7)="","",INDEX(LookupData!Y:Y,$AK7)))) | Z7: =IF($AK7="","",IF($AK7=0,"",IF(INDEX(LookupData!Z:Z,$AK7)="","",INDEX(LookupData!Z:Z,$AK7)))) | AA7: =IF($AK7="","",IF($AK7=0,"",IF(INDEX(LookupData!AA:AA,$AK7)="","",INDEX(LookupData!AA:AA,$AK7)))) | AB7: =IF($AK7="","",IF($AK7=0,"",IF(INDEX(LookupData!AB:AB,$AK7)="","",INDEX(LookupData!AB:AB,$AK7)))) | AC7: =IF($AK7="","",IF($AK7=0,"",IF(INDEX(LookupData!AC:AC,$AK7)="","",INDEX(LookupData!AC:AC,$AK7)))) | AD7: =IF($AK7="","",IF($AK7=0,"",IF(INDEX(LookupData!AD:AD,$AK7)="","",INDEX(LookupData!AD:AD,$AK7)))) | AE7: =IF($AK7="","",IF($AK7=0,"",IF(INDEX(LookupData!AE:AE,$AK7)="","",INDEX(LookupData!AE:AE,$AK7)))) | AF7: =IF($AK7="","",IF($AK7=0,"",IF(INDEX(LookupData!AF:AF,$AK7)="","",INDEX(LookupData!AF:AF,$AK7)))) | AG7: =IF($AK7="","",IF($AK7=0,"",IF(INDEX(LookupData!AG:AG,$AK7)="","",INDEX(LookupData!AG:AG,$AK7)))) | AH7: =IF($AK7="","",IF($AK7=0,"",IF(INDEX(LookupData!AH:AH,$AK7)="","",INDEX(LookupData!AH:AH,$AK7)))) | AI7: =IF($AK7="","",IF($AK7=0,"",IF(INDEX(LookupData!AI:AI,$AK7)="","",HYPERLINK(INDEX(LookupData!AI:AI,$AK7),"Open")))) | AK7: =IF(AL7="","",IFERROR(MATCH(AL7,LookupData!$A:$A,0),0)) | AL7: =IF(TRIM($A7)="","",UPPER(TRIM($A7))) | AM7: =IF(AL7="",AM6,IF(AM6="",AL7,AM6&"|"&AL7)) | AO7: =IF(MID($AN$1,1441,240)="","|",MID($AN$1,1441,240)) -> |
B8: =IF($AK8="","",IF($AK8=0,"not in the database",IF(INDEX(LookupData!B:B,$AK8)="","",INDEX(LookupData!B:B,$AK8)))) | C8: =IF($AK8="","",IF($AK8=0,"",IF(INDEX(LookupData!C:C,$AK8)="","",INDEX(LookupData!C:C,$AK8)))) | D8: =IF($AK8="","",IF($AK8=0,"",IF(INDEX(LookupData!D:D,$AK8)="","",INDEX(LookupData!D:D,$AK8)))) | E8: =IF($AK8="","",IF($AK8=0,"",IF(INDEX(LookupData!E:E,$AK8)="","",INDEX(LookupData!E:E,$AK8)))) | F8: =IF($AK8="","",IF($AK8=0,"",IF(INDEX(LookupData!F:F,$AK8)="","",INDEX(LookupData!F:F,$AK8)))) | G8: =IF($AK8="","",IF($AK8=0,"",IF(INDEX(LookupData!G:G,$AK8)="","",INDEX(LookupData!G:G,$AK8)))) | H8: =IF($AK8="","",IF($AK8=0,"",IF(INDEX(LookupData!H:H,$AK8)="","",INDEX(LookupData!H:H,$AK8)))) | I8: =IF($AK8="","",IF($AK8=0,"",IF(INDEX(LookupData!I:I,$AK8)="","",INDEX(LookupData!I:I,$AK8)))) | J8: =IF($AK8="","",IF($AK8=0,"",IF(INDEX(LookupData!J:J,$AK8)="","",INDEX(LookupData!J:J,$AK8)))) | K8: =IF($AK8="","",IF($AK8=0,"",IF(INDEX(LookupData!K:K,$AK8)="","",INDEX(LookupData!K:K,$AK8)))) | L8: =IF($AK8="","",IF($AK8=0,"",IF(INDEX(LookupData!L:L,$AK8)="","",INDEX(LookupData!L:L,$AK8)))) | M8: =IF($AK8="","",IF($AK8=0,"",IF(INDEX(LookupData!M:M,$AK8)="","",INDEX(LookupData!M:M,$AK8)))) | N8: =IF($AK8="","",IF($AK8=0,"",IF(INDEX(LookupData!N:N,$AK8)="","",INDEX(LookupData!N:N,$AK8)))) | O8: =IF($AK8="","",IF($AK8=0,"",IF(INDEX(LookupData!O:O,$AK8)="","",INDEX(LookupData!O:O,$AK8)))) | P8: =IF($AK8="","",IF($AK8=0,"",IF(INDEX(LookupData!P:P,$AK8)="","",INDEX(LookupData!P:P,$AK8)))) | Q8: =IF($AK8="","",IF($AK8=0,"",IF(INDEX(LookupData!Q:Q,$AK8)="","",INDEX(LookupData!Q:Q,$AK8)))) | R8: =IF($AK8="","",IF($AK8=0,"",IF(INDEX(LookupData!R:R,$AK8)="","",INDEX(LookupData!R:R,$AK8)))) | S8: =IF($AK8="","",IF($AK8=0,"",IF(INDEX(LookupData!S:S,$AK8)="","",INDEX(LookupData!S:S,$AK8)))) | T8: =IF($AK8="","",IF($AK8=0,"",IF(INDEX(LookupData!T:T,$AK8)="","",INDEX(LookupData!T:T,$AK8)))) | U8: =IF($AK8="","",IF($AK8=0,"",IF(INDEX(LookupData!U:U,$AK8)="","",INDEX(LookupData!U:U,$AK8)))) | V8: =IF($AK8="","",IF($AK8=0,"",IF(INDEX(LookupData!V:V,$AK8)="","",INDEX(LookupData!V:V,$AK8)))) | W8: =IF($AK8="","",IF($AK8=0,"",IF(INDEX(LookupData!W:W,$AK8)="","",INDEX(LookupData!W:W,$AK8)))) | X8: =IF($AK8="","",IF($AK8=0,"",IF(INDEX(LookupData!X:X,$AK8)="","",INDEX(LookupData!X:X,$AK8)))) | Y8: =IF($AK8="","",IF($AK8=0,"",IF(INDEX(LookupData!Y:Y,$AK8)="","",INDEX(LookupData!Y:Y,$AK8)))) | Z8: =IF($AK8="","",IF($AK8=0,"",IF(INDEX(LookupData!Z:Z,$AK8)="","",INDEX(LookupData!Z:Z,$AK8)))) | AA8: =IF($AK8="","",IF($AK8=0,"",IF(INDEX(LookupData!AA:AA,$AK8)="","",INDEX(LookupData!AA:AA,$AK8)))) | AB8: =IF($AK8="","",IF($AK8=0,"",IF(INDEX(LookupData!AB:AB,$AK8)="","",INDEX(LookupData!AB:AB,$AK8)))) | AC8: =IF($AK8="","",IF($AK8=0,"",IF(INDEX(LookupData!AC:AC,$AK8)="","",INDEX(LookupData!AC:AC,$AK8)))) | AD8: =IF($AK8="","",IF($AK8=0,"",IF(INDEX(LookupData!AD:AD,$AK8)="","",INDEX(LookupData!AD:AD,$AK8)))) | AE8: =IF($AK8="","",IF($AK8=0,"",IF(INDEX(LookupData!AE:AE,$AK8)="","",INDEX(LookupData!AE:AE,$AK8)))) | AF8: =IF($AK8="","",IF($AK8=0,"",IF(INDEX(LookupData!AF:AF,$AK8)="","",INDEX(LookupData!AF:AF,$AK8)))) | AG8: =IF($AK8="","",IF($AK8=0,"",IF(INDEX(LookupData!AG:AG,$AK8)="","",INDEX(LookupData!AG:AG,$AK8)))) | AH8: =IF($AK8="","",IF($AK8=0,"",IF(INDEX(LookupData!AH:AH,$AK8)="","",INDEX(LookupData!AH:AH,$AK8)))) | AI8: =IF($AK8="","",IF($AK8=0,"",IF(INDEX(LookupData!AI:AI,$AK8)="","",HYPERLINK(INDEX(LookupData!AI:AI,$AK8),"Open")))) | AK8: =IF(AL8="","",IFERROR(MATCH(AL8,LookupData!$A:$A,0),0)) | AL8: =IF(TRIM($A8)="","",UPPER(TRIM($A8))) | AM8: =IF(AL8="",AM7,IF(AM7="",AL8,AM7&"|"&AL8)) | AO8: =IF(MID($AN$1,1681,240)="","|",MID($AN$1,1681,240)) -> |
B9: =IF($AK9="","",IF($AK9=0,"not in the database",IF(INDEX(LookupData!B:B,$AK9)="","",INDEX(LookupData!B:B,$AK9)))) | C9: =IF($AK9="","",IF($AK9=0,"",IF(INDEX(LookupData!C:C,$AK9)="","",INDEX(LookupData!C:C,$AK9)))) | D9: =IF($AK9="","",IF($AK9=0,"",IF(INDEX(LookupData!D:D,$AK9)="","",INDEX(LookupData!D:D,$AK9)))) | E9: =IF($AK9="","",IF($AK9=0,"",IF(INDEX(LookupData!E:E,$AK9)="","",INDEX(LookupData!E:E,$AK9)))) | F9: =IF($AK9="","",IF($AK9=0,"",IF(INDEX(LookupData!F:F,$AK9)="","",INDEX(LookupData!F:F,$AK9)))) | G9: =IF($AK9="","",IF($AK9=0,"",IF(INDEX(LookupData!G:G,$AK9)="","",INDEX(LookupData!G:G,$AK9)))) | H9: =IF($AK9="","",IF($AK9=0,"",IF(INDEX(LookupData!H:H,$AK9)="","",INDEX(LookupData!H:H,$AK9)))) | I9: =IF($AK9="","",IF($AK9=0,"",IF(INDEX(LookupData!I:I,$AK9)="","",INDEX(LookupData!I:I,$AK9)))) | J9: =IF($AK9="","",IF($AK9=0,"",IF(INDEX(LookupData!J:J,$AK9)="","",INDEX(LookupData!J:J,$AK9)))) | K9: =IF($AK9="","",IF($AK9=0,"",IF(INDEX(LookupData!K:K,$AK9)="","",INDEX(LookupData!K:K,$AK9)))) | L9: =IF($AK9="","",IF($AK9=0,"",IF(INDEX(LookupData!L:L,$AK9)="","",INDEX(LookupData!L:L,$AK9)))) | M9: =IF($AK9="","",IF($AK9=0,"",IF(INDEX(LookupData!M:M,$AK9)="","",INDEX(LookupData!M:M,$AK9)))) | N9: =IF($AK9="","",IF($AK9=0,"",IF(INDEX(LookupData!N:N,$AK9)="","",INDEX(LookupData!N:N,$AK9)))) | O9: =IF($AK9="","",IF($AK9=0,"",IF(INDEX(LookupData!O:O,$AK9)="","",INDEX(LookupData!O:O,$AK9)))) | P9: =IF($AK9="","",IF($AK9=0,"",IF(INDEX(LookupData!P:P,$AK9)="","",INDEX(LookupData!P:P,$AK9)))) | Q9: =IF($AK9="","",IF($AK9=0,"",IF(INDEX(LookupData!Q:Q,$AK9)="","",INDEX(LookupData!Q:Q,$AK9)))) | R9: =IF($AK9="","",IF($AK9=0,"",IF(INDEX(LookupData!R:R,$AK9)="","",INDEX(LookupData!R:R,$AK9)))) | S9: =IF($AK9="","",IF($AK9=0,"",IF(INDEX(LookupData!S:S,$AK9)="","",INDEX(LookupData!S:S,$AK9)))) | T9: =IF($AK9="","",IF($AK9=0,"",IF(INDEX(LookupData!T:T,$AK9)="","",INDEX(LookupData!T:T,$AK9)))) | U9: =IF($AK9="","",IF($AK9=0,"",IF(INDEX(LookupData!U:U,$AK9)="","",INDEX(LookupData!U:U,$AK9)))) | V9: =IF($AK9="","",IF($AK9=0,"",IF(INDEX(LookupData!V:V,$AK9)="","",INDEX(LookupData!V:V,$AK9)))) | W9: =IF($AK9="","",IF($AK9=0,"",IF(INDEX(LookupData!W:W,$AK9)="","",INDEX(LookupData!W:W,$AK9)))) | X9: =IF($AK9="","",IF($AK9=0,"",IF(INDEX(LookupData!X:X,$AK9)="","",INDEX(LookupData!X:X,$AK9)))) | Y9: =IF($AK9="","",IF($AK9=0,"",IF(INDEX(LookupData!Y:Y,$AK9)="","",INDEX(LookupData!Y:Y,$AK9)))) | Z9: =IF($AK9="","",IF($AK9=0,"",IF(INDEX(LookupData!Z:Z,$AK9)="","",INDEX(LookupData!Z:Z,$AK9)))) | AA9: =IF($AK9="","",IF($AK9=0,"",IF(INDEX(LookupData!AA:AA,$AK9)="","",INDEX(LookupData!AA:AA,$AK9)))) | AB9: =IF($AK9="","",IF($AK9=0,"",IF(INDEX(LookupData!AB:AB,$AK9)="","",INDEX(LookupData!AB:AB,$AK9)))) | AC9: =IF($AK9="","",IF($AK9=0,"",IF(INDEX(LookupData!AC:AC,$AK9)="","",INDEX(LookupData!AC:AC,$AK9)))) | AD9: =IF($AK9="","",IF($AK9=0,"",IF(INDEX(LookupData!AD:AD,$AK9)="","",INDEX(LookupData!AD:AD,$AK9)))) | AE9: =IF($AK9="","",IF($AK9=0,"",IF(INDEX(LookupData!AE:AE,$AK9)="","",INDEX(LookupData!AE:AE,$AK9)))) | AF9: =IF($AK9="","",IF($AK9=0,"",IF(INDEX(LookupData!AF:AF,$AK9)="","",INDEX(LookupData!AF:AF,$AK9)))) | AG9: =IF($AK9="","",IF($AK9=0,"",IF(INDEX(LookupData!AG:AG,$AK9)="","",INDEX(LookupData!AG:AG,$AK9)))) | AH9: =IF($AK9="","",IF($AK9=0,"",IF(INDEX(LookupData!AH:AH,$AK9)="","",INDEX(LookupData!AH:AH,$AK9)))) | AI9: =IF($AK9="","",IF($AK9=0,"",IF(INDEX(LookupData!AI:AI,$AK9)="","",HYPERLINK(INDEX(LookupData!AI:AI,$AK9),"Open")))) | AK9: =IF(AL9="","",IFERROR(MATCH(AL9,LookupData!$A:$A,0),0)) | AL9: =IF(TRIM($A9)="","",UPPER(TRIM($A9))) | AM9: =IF(AL9="",AM8,IF(AM8="",AL9,AM8&"|"&AL9)) | AO9: =IF(MID($AN$1,1921,240)="","|",MID($AN$1,1921,240)) -> |
B10: =IF($AK10="","",IF($AK10=0,"not in the database",IF(INDEX(LookupData!B:B,$AK10)="","",INDEX(LookupData!B:B,$AK10)))) | C10: =IF($AK10="","",IF($AK10=0,"",IF(INDEX(LookupData!C:C,$AK10)="","",INDEX(LookupData!C:C,$AK10)))) | D10: =IF($AK10="","",IF($AK10=0,"",IF(INDEX(LookupData!D:D,$AK10)="","",INDEX(LookupData!D:D,$AK10)))) | E10: =IF($AK10="","",IF($AK10=0,"",IF(INDEX(LookupData!E:E,$AK10)="","",INDEX(LookupData!E:E,$AK10)))) | F10: =IF($AK10="","",IF($AK10=0,"",IF(INDEX(LookupData!F:F,$AK10)="","",INDEX(LookupData!F:F,$AK10)))) | G10: =IF($AK10="","",IF($AK10=0,"",IF(INDEX(LookupData!G:G,$AK10)="","",INDEX(LookupData!G:G,$AK10)))) | H10: =IF($AK10="","",IF($AK10=0,"",IF(INDEX(LookupData!H:H,$AK10)="","",INDEX(LookupData!H:H,$AK10)))) | I10: =IF($AK10="","",IF($AK10=0,"",IF(INDEX(LookupData!I:I,$AK10)="","",INDEX(LookupData!I:I,$AK10)))) | J10: =IF($AK10="","",IF($AK10=0,"",IF(INDEX(LookupData!J:J,$AK10)="","",INDEX(LookupData!J:J,$AK10)))) | K10: =IF($AK10="","",IF($AK10=0,"",IF(INDEX(LookupData!K:K,$AK10)="","",INDEX(LookupData!K:K,$AK10)))) | L10: =IF($AK10="","",IF($AK10=0,"",IF(INDEX(LookupData!L:L,$AK10)="","",INDEX(LookupData!L:L,$AK10)))) | M10: =IF($AK10="","",IF($AK10=0,"",IF(INDEX(LookupData!M:M,$AK10)="","",INDEX(LookupData!M:M,$AK10)))) | N10: =IF($AK10="","",IF($AK10=0,"",IF(INDEX(LookupData!N:N,$AK10)="","",INDEX(LookupData!N:N,$AK10)))) | O10: =IF($AK10="","",IF($AK10=0,"",IF(INDEX(LookupData!O:O,$AK10)="","",INDEX(LookupData!O:O,$AK10)))) | P10: =IF($AK10="","",IF($AK10=0,"",IF(INDEX(LookupData!P:P,$AK10)="","",INDEX(LookupData!P:P,$AK10)))) | Q10: =IF($AK10="","",IF($AK10=0,"",IF(INDEX(LookupData!Q:Q,$AK10)="","",INDEX(LookupData!Q:Q,$AK10)))) | R10: =IF($AK10="","",IF($AK10=0,"",IF(INDEX(LookupData!R:R,$AK10)="","",INDEX(LookupData!R:R,$AK10)))) | S10: =IF($AK10="","",IF($AK10=0,"",IF(INDEX(LookupData!S:S,$AK10)="","",INDEX(LookupData!S:S,$AK10)))) | T10: =IF($AK10="","",IF($AK10=0,"",IF(INDEX(LookupData!T:T,$AK10)="","",INDEX(LookupData!T:T,$AK10)))) | U10: =IF($AK10="","",IF($AK10=0,"",IF(INDEX(LookupData!U:U,$AK10)="","",INDEX(LookupData!U:U,$AK10)))) | V10: =IF($AK10="","",IF($AK10=0,"",IF(INDEX(LookupData!V:V,$AK10)="","",INDEX(LookupData!V:V,$AK10)))) | W10: =IF($AK10="","",IF($AK10=0,"",IF(INDEX(LookupData!W:W,$AK10)="","",INDEX(LookupData!W:W,$AK10)))) | X10: =IF($AK10="","",IF($AK10=0,"",IF(INDEX(LookupData!X:X,$AK10)="","",INDEX(LookupData!X:X,$AK10)))) | Y10: =IF($AK10="","",IF($AK10=0,"",IF(INDEX(LookupData!Y:Y,$AK10)="","",INDEX(LookupData!Y:Y,$AK10)))) | Z10: =IF($AK10="","",IF($AK10=0,"",IF(INDEX(LookupData!Z:Z,$AK10)="","",INDEX(LookupData!Z:Z,$AK10)))) | AA10: =IF($AK10="","",IF($AK10=0,"",IF(INDEX(LookupData!AA:AA,$AK10)="","",INDEX(LookupData!AA:AA,$AK10)))) | AB10: =IF($AK10="","",IF($AK10=0,"",IF(INDEX(LookupData!AB:AB,$AK10)="","",INDEX(LookupData!AB:AB,$AK10)))) | AC10: =IF($AK10="","",IF($AK10=0,"",IF(INDEX(LookupData!AC:AC,$AK10)="","",INDEX(LookupData!AC:AC,$AK10)))) | AD10: =IF($AK10="","",IF($AK10=0,"",IF(INDEX(LookupData!AD:AD,$AK10)="","",INDEX(LookupData!AD:AD,$AK10)))) | AE10: =IF($AK10="","",IF($AK10=0,"",IF(INDEX(LookupData!AE:AE,$AK10)="","",INDEX(LookupData!AE:AE,$AK10)))) | AF10: =IF($AK10="","",IF($AK10=0,"",IF(INDEX(LookupData!AF:AF,$AK10)="","",INDEX(LookupData!AF:AF,$AK10)))) | AG10: =IF($AK10="","",IF($AK10=0,"",IF(INDEX(LookupData!AG:AG,$AK10)="","",INDEX(LookupData!AG:AG,$AK10)))) | AH10: =IF($AK10="","",IF($AK10=0,"",IF(INDEX(LookupData!AH:AH,$AK10)="","",INDEX(LookupData!AH:AH,$AK10)))) | AI10: =IF($AK10="","",IF($AK10=0,"",IF(INDEX(LookupData!AI:AI,$AK10)="","",HYPERLINK(INDEX(LookupData!AI:AI,$AK10),"Open")))) | AK10: =IF(AL10="","",IFERROR(MATCH(AL10,LookupData!$A:$A,0),0)) | AL10: =IF(TRIM($A10)="","",UPPER(TRIM($A10))) | AM10: =IF(AL10="",AM9,IF(AM9="",AL10,AM9&"|"&AL10)) | AO10: =IF(MID($AN$1,2161,240)="","|",MID($AN$1,2161,240)) -> |
B11: =IF($AK11="","",IF($AK11=0,"not in the database",IF(INDEX(LookupData!B:B,$AK11)="","",INDEX(LookupData!B:B,$AK11)))) | C11: =IF($AK11="","",IF($AK11=0,"",IF(INDEX(LookupData!C:C,$AK11)="","",INDEX(LookupData!C:C,$AK11)))) | D11: =IF($AK11="","",IF($AK11=0,"",IF(INDEX(LookupData!D:D,$AK11)="","",INDEX(LookupData!D:D,$AK11)))) | E11: =IF($AK11="","",IF($AK11=0,"",IF(INDEX(LookupData!E:E,$AK11)="","",INDEX(LookupData!E:E,$AK11)))) | F11: =IF($AK11="","",IF($AK11=0,"",IF(INDEX(LookupData!F:F,$AK11)="","",INDEX(LookupData!F:F,$AK11)))) | G11: =IF($AK11="","",IF($AK11=0,"",IF(INDEX(LookupData!G:G,$AK11)="","",INDEX(LookupData!G:G,$AK11)))) | H11: =IF($AK11="","",IF($AK11=0,"",IF(INDEX(LookupData!H:H,$AK11)="","",INDEX(LookupData!H:H,$AK11)))) | I11: =IF($AK11="","",IF($AK11=0,"",IF(INDEX(LookupData!I:I,$AK11)="","",INDEX(LookupData!I:I,$AK11)))) | J11: =IF($AK11="","",IF($AK11=0,"",IF(INDEX(LookupData!J:J,$AK11)="","",INDEX(LookupData!J:J,$AK11)))) | K11: =IF($AK11="","",IF($AK11=0,"",IF(INDEX(LookupData!K:K,$AK11)="","",INDEX(LookupData!K:K,$AK11)))) | L11: =IF($AK11="","",IF($AK11=0,"",IF(INDEX(LookupData!L:L,$AK11)="","",INDEX(LookupData!L:L,$AK11)))) | M11: =IF($AK11="","",IF($AK11=0,"",IF(INDEX(LookupData!M:M,$AK11)="","",INDEX(LookupData!M:M,$AK11)))) | N11: =IF($AK11="","",IF($AK11=0,"",IF(INDEX(LookupData!N:N,$AK11)="","",INDEX(LookupData!N:N,$AK11)))) | O11: =IF($AK11="","",IF($AK11=0,"",IF(INDEX(LookupData!O:O,$AK11)="","",INDEX(LookupData!O:O,$AK11)))) | P11: =IF($AK11="","",IF($AK11=0,"",IF(INDEX(LookupData!P:P,$AK11)="","",INDEX(LookupData!P:P,$AK11)))) | Q11: =IF($AK11="","",IF($AK11=0,"",IF(INDEX(LookupData!Q:Q,$AK11)="","",INDEX(LookupData!Q:Q,$AK11)))) | R11: =IF($AK11="","",IF($AK11=0,"",IF(INDEX(LookupData!R:R,$AK11)="","",INDEX(LookupData!R:R,$AK11)))) | S11: =IF($AK11="","",IF($AK11=0,"",IF(INDEX(LookupData!S:S,$AK11)="","",INDEX(LookupData!S:S,$AK11)))) | T11: =IF($AK11="","",IF($AK11=0,"",IF(INDEX(LookupData!T:T,$AK11)="","",INDEX(LookupData!T:T,$AK11)))) | U11: =IF($AK11="","",IF($AK11=0,"",IF(INDEX(LookupData!U:U,$AK11)="","",INDEX(LookupData!U:U,$AK11)))) | V11: =IF($AK11="","",IF($AK11=0,"",IF(INDEX(LookupData!V:V,$AK11)="","",INDEX(LookupData!V:V,$AK11)))) | W11: =IF($AK11="","",IF($AK11=0,"",IF(INDEX(LookupData!W:W,$AK11)="","",INDEX(LookupData!W:W,$AK11)))) | X11: =IF($AK11="","",IF($AK11=0,"",IF(INDEX(LookupData!X:X,$AK11)="","",INDEX(LookupData!X:X,$AK11)))) | Y11: =IF($AK11="","",IF($AK11=0,"",IF(INDEX(LookupData!Y:Y,$AK11)="","",INDEX(LookupData!Y:Y,$AK11)))) | Z11: =IF($AK11="","",IF($AK11=0,"",IF(INDEX(LookupData!Z:Z,$AK11)="","",INDEX(LookupData!Z:Z,$AK11)))) | AA11: =IF($AK11="","",IF($AK11=0,"",IF(INDEX(LookupData!AA:AA,$AK11)="","",INDEX(LookupData!AA:AA,$AK11)))) | AB11: =IF($AK11="","",IF($AK11=0,"",IF(INDEX(LookupData!AB:AB,$AK11)="","",INDEX(LookupData!AB:AB,$AK11)))) | AC11: =IF($AK11="","",IF($AK11=0,"",IF(INDEX(LookupData!AC:AC,$AK11)="","",INDEX(LookupData!AC:AC,$AK11)))) | AD11: =IF($AK11="","",IF($AK11=0,"",IF(INDEX(LookupData!AD:AD,$AK11)="","",INDEX(LookupData!AD:AD,$AK11)))) | AE11: =IF($AK11="","",IF($AK11=0,"",IF(INDEX(LookupData!AE:AE,$AK11)="","",INDEX(LookupData!AE:AE,$AK11)))) | AF11: =IF($AK11="","",IF($AK11=0,"",IF(INDEX(LookupData!AF:AF,$AK11)="","",INDEX(LookupData!AF:AF,$AK11)))) | AG11: =IF($AK11="","",IF($AK11=0,"",IF(INDEX(LookupData!AG:AG,$AK11)="","",INDEX(LookupData!AG:AG,$AK11)))) | AH11: =IF($AK11="","",IF($AK11=0,"",IF(INDEX(LookupData!AH:AH,$AK11)="","",INDEX(LookupData!AH:AH,$AK11)))) | AI11: =IF($AK11="","",IF($AK11=0,"",IF(INDEX(LookupData!AI:AI,$AK11)="","",HYPERLINK(INDEX(LookupData!AI:AI,$AK11),"Open")))) | AK11: =IF(AL11="","",IFERROR(MATCH(AL11,LookupData!$A:$A,0),0)) | AL11: =IF(TRIM($A11)="","",UPPER(TRIM($A11))) | AM11: =IF(AL11="",AM10,IF(AM10="",AL11,AM10&"|"&AL11)) | AO11: =IF(MID($AN$1,2401,240)="","|",MID($AN$1,2401,240)) -> |
B12: =IF($AK12="","",IF($AK12=0,"not in the database",IF(INDEX(LookupData!B:B,$AK12)="","",INDEX(LookupData!B:B,$AK12)))) | C12: =IF($AK12="","",IF($AK12=0,"",IF(INDEX(LookupData!C:C,$AK12)="","",INDEX(LookupData!C:C,$AK12)))) | D12: =IF($AK12="","",IF($AK12=0,"",IF(INDEX(LookupData!D:D,$AK12)="","",INDEX(LookupData!D:D,$AK12)))) | E12: =IF($AK12="","",IF($AK12=0,"",IF(INDEX(LookupData!E:E,$AK12)="","",INDEX(LookupData!E:E,$AK12)))) | F12: =IF($AK12="","",IF($AK12=0,"",IF(INDEX(LookupData!F:F,$AK12)="","",INDEX(LookupData!F:F,$AK12)))) | G12: =IF($AK12="","",IF($AK12=0,"",IF(INDEX(LookupData!G:G,$AK12)="","",INDEX(LookupData!G:G,$AK12)))) | H12: =IF($AK12="","",IF($AK12=0,"",IF(INDEX(LookupData!H:H,$AK12)="","",INDEX(LookupData!H:H,$AK12)))) | I12: =IF($AK12="","",IF($AK12=0,"",IF(INDEX(LookupData!I:I,$AK12)="","",INDEX(LookupData!I:I,$AK12)))) | J12: =IF($AK12="","",IF($AK12=0,"",IF(INDEX(LookupData!J:J,$AK12)="","",INDEX(LookupData!J:J,$AK12)))) | K12: =IF($AK12="","",IF($AK12=0,"",IF(INDEX(LookupData!K:K,$AK12)="","",INDEX(LookupData!K:K,$AK12)))) | L12: =IF($AK12="","",IF($AK12=0,"",IF(INDEX(LookupData!L:L,$AK12)="","",INDEX(LookupData!L:L,$AK12)))) | M12: =IF($AK12="","",IF($AK12=0,"",IF(INDEX(LookupData!M:M,$AK12)="","",INDEX(LookupData!M:M,$AK12)))) | N12: =IF($AK12="","",IF($AK12=0,"",IF(INDEX(LookupData!N:N,$AK12)="","",INDEX(LookupData!N:N,$AK12)))) | O12: =IF($AK12="","",IF($AK12=0,"",IF(INDEX(LookupData!O:O,$AK12)="","",INDEX(LookupData!O:O,$AK12)))) | P12: =IF($AK12="","",IF($AK12=0,"",IF(INDEX(LookupData!P:P,$AK12)="","",INDEX(LookupData!P:P,$AK12)))) | Q12: =IF($AK12="","",IF($AK12=0,"",IF(INDEX(LookupData!Q:Q,$AK12)="","",INDEX(LookupData!Q:Q,$AK12)))) | R12: =IF($AK12="","",IF($AK12=0,"",IF(INDEX(LookupData!R:R,$AK12)="","",INDEX(LookupData!R:R,$AK12)))) | S12: =IF($AK12="","",IF($AK12=0,"",IF(INDEX(LookupData!S:S,$AK12)="","",INDEX(LookupData!S:S,$AK12)))) | T12: =IF($AK12="","",IF($AK12=0,"",IF(INDEX(LookupData!T:T,$AK12)="","",INDEX(LookupData!T:T,$AK12)))) | U12: =IF($AK12="","",IF($AK12=0,"",IF(INDEX(LookupData!U:U,$AK12)="","",INDEX(LookupData!U:U,$AK12)))) | V12: =IF($AK12="","",IF($AK12=0,"",IF(INDEX(LookupData!V:V,$AK12)="","",INDEX(LookupData!V:V,$AK12)))) | W12: =IF($AK12="","",IF($AK12=0,"",IF(INDEX(LookupData!W:W,$AK12)="","",INDEX(LookupData!W:W,$AK12)))) | X12: =IF($AK12="","",IF($AK12=0,"",IF(INDEX(LookupData!X:X,$AK12)="","",INDEX(LookupData!X:X,$AK12)))) | Y12: =IF($AK12="","",IF($AK12=0,"",IF(INDEX(LookupData!Y:Y,$AK12)="","",INDEX(LookupData!Y:Y,$AK12)))) | Z12: =IF($AK12="","",IF($AK12=0,"",IF(INDEX(LookupData!Z:Z,$AK12)="","",INDEX(LookupData!Z:Z,$AK12)))) | AA12: =IF($AK12="","",IF($AK12=0,"",IF(INDEX(LookupData!AA:AA,$AK12)="","",INDEX(LookupData!AA:AA,$AK12)))) | AB12: =IF($AK12="","",IF($AK12=0,"",IF(INDEX(LookupData!AB:AB,$AK12)="","",INDEX(LookupData!AB:AB,$AK12)))) | AC12: =IF($AK12="","",IF($AK12=0,"",IF(INDEX(LookupData!AC:AC,$AK12)="","",INDEX(LookupData!AC:AC,$AK12)))) | AD12: =IF($AK12="","",IF($AK12=0,"",IF(INDEX(LookupData!AD:AD,$AK12)="","",INDEX(LookupData!AD:AD,$AK12)))) | AE12: =IF($AK12="","",IF($AK12=0,"",IF(INDEX(LookupData!AE:AE,$AK12)="","",INDEX(LookupData!AE:AE,$AK12)))) | AF12: =IF($AK12="","",IF($AK12=0,"",IF(INDEX(LookupData!AF:AF,$AK12)="","",INDEX(LookupData!AF:AF,$AK12)))) | AG12: =IF($AK12="","",IF($AK12=0,"",IF(INDEX(LookupData!AG:AG,$AK12)="","",INDEX(LookupData!AG:AG,$AK12)))) | AH12: =IF($AK12="","",IF($AK12=0,"",IF(INDEX(LookupData!AH:AH,$AK12)="","",INDEX(LookupData!AH:AH,$AK12)))) | AI12: =IF($AK12="","",IF($AK12=0,"",IF(INDEX(LookupData!AI:AI,$AK12)="","",HYPERLINK(INDEX(LookupData!AI:AI,$AK12),"Open")))) | AK12: =IF(AL12="","",IFERROR(MATCH(AL12,LookupData!$A:$A,0),0)) | AL12: =IF(TRIM($A12)="","",UPPER(TRIM($A12))) | AM12: =IF(AL12="",AM11,IF(AM11="",AL12,AM11&"|"&AL12)) | AO12: =IF(MID($AN$1,2641,240)="","|",MID($AN$1,2641,240)) -> |
B13: =IF($AK13="","",IF($AK13=0,"not in the database",IF(INDEX(LookupData!B:B,$AK13)="","",INDEX(LookupData!B:B,$AK13)))) | C13: =IF($AK13="","",IF($AK13=0,"",IF(INDEX(LookupData!C:C,$AK13)="","",INDEX(LookupData!C:C,$AK13)))) | D13: =IF($AK13="","",IF($AK13=0,"",IF(INDEX(LookupData!D:D,$AK13)="","",INDEX(LookupData!D:D,$AK13)))) | E13: =IF($AK13="","",IF($AK13=0,"",IF(INDEX(LookupData!E:E,$AK13)="","",INDEX(LookupData!E:E,$AK13)))) | F13: =IF($AK13="","",IF($AK13=0,"",IF(INDEX(LookupData!F:F,$AK13)="","",INDEX(LookupData!F:F,$AK13)))) | G13: =IF($AK13="","",IF($AK13=0,"",IF(INDEX(LookupData!G:G,$AK13)="","",INDEX(LookupData!G:G,$AK13)))) | H13: =IF($AK13="","",IF($AK13=0,"",IF(INDEX(LookupData!H:H,$AK13)="","",INDEX(LookupData!H:H,$AK13)))) | I13: =IF($AK13="","",IF($AK13=0,"",IF(INDEX(LookupData!I:I,$AK13)="","",INDEX(LookupData!I:I,$AK13)))) | J13: =IF($AK13="","",IF($AK13=0,"",IF(INDEX(LookupData!J:J,$AK13)="","",INDEX(LookupData!J:J,$AK13)))) | K13: =IF($AK13="","",IF($AK13=0,"",IF(INDEX(LookupData!K:K,$AK13)="","",INDEX(LookupData!K:K,$AK13)))) | L13: =IF($AK13="","",IF($AK13=0,"",IF(INDEX(LookupData!L:L,$AK13)="","",INDEX(LookupData!L:L,$AK13)))) | M13: =IF($AK13="","",IF($AK13=0,"",IF(INDEX(LookupData!M:M,$AK13)="","",INDEX(LookupData!M:M,$AK13)))) | N13: =IF($AK13="","",IF($AK13=0,"",IF(INDEX(LookupData!N:N,$AK13)="","",INDEX(LookupData!N:N,$AK13)))) | O13: =IF($AK13="","",IF($AK13=0,"",IF(INDEX(LookupData!O:O,$AK13)="","",INDEX(LookupData!O:O,$AK13)))) | P13: =IF($AK13="","",IF($AK13=0,"",IF(INDEX(LookupData!P:P,$AK13)="","",INDEX(LookupData!P:P,$AK13)))) | Q13: =IF($AK13="","",IF($AK13=0,"",IF(INDEX(LookupData!Q:Q,$AK13)="","",INDEX(LookupData!Q:Q,$AK13)))) | R13: =IF($AK13="","",IF($AK13=0,"",IF(INDEX(LookupData!R:R,$AK13)="","",INDEX(LookupData!R:R,$AK13)))) | S13: =IF($AK13="","",IF($AK13=0,"",IF(INDEX(LookupData!S:S,$AK13)="","",INDEX(LookupData!S:S,$AK13)))) | T13: =IF($AK13="","",IF($AK13=0,"",IF(INDEX(LookupData!T:T,$AK13)="","",INDEX(LookupData!T:T,$AK13)))) | U13: =IF($AK13="","",IF($AK13=0,"",IF(INDEX(LookupData!U:U,$AK13)="","",INDEX(LookupData!U:U,$AK13)))) | V13: =IF($AK13="","",IF($AK13=0,"",IF(INDEX(LookupData!V:V,$AK13)="","",INDEX(LookupData!V:V,$AK13)))) | W13: =IF($AK13="","",IF($AK13=0,"",IF(INDEX(LookupData!W:W,$AK13)="","",INDEX(LookupData!W:W,$AK13)))) | X13: =IF($AK13="","",IF($AK13=0,"",IF(INDEX(LookupData!X:X,$AK13)="","",INDEX(LookupData!X:X,$AK13)))) | Y13: =IF($AK13="","",IF($AK13=0,"",IF(INDEX(LookupData!Y:Y,$AK13)="","",INDEX(LookupData!Y:Y,$AK13)))) | Z13: =IF($AK13="","",IF($AK13=0,"",IF(INDEX(LookupData!Z:Z,$AK13)="","",INDEX(LookupData!Z:Z,$AK13)))) | AA13: =IF($AK13="","",IF($AK13=0,"",IF(INDEX(LookupData!AA:AA,$AK13)="","",INDEX(LookupData!AA:AA,$AK13)))) | AB13: =IF($AK13="","",IF($AK13=0,"",IF(INDEX(LookupData!AB:AB,$AK13)="","",INDEX(LookupData!AB:AB,$AK13)))) | AC13: =IF($AK13="","",IF($AK13=0,"",IF(INDEX(LookupData!AC:AC,$AK13)="","",INDEX(LookupData!AC:AC,$AK13)))) | AD13: =IF($AK13="","",IF($AK13=0,"",IF(INDEX(LookupData!AD:AD,$AK13)="","",INDEX(LookupData!AD:AD,$AK13)))) | AE13: =IF($AK13="","",IF($AK13=0,"",IF(INDEX(LookupData!AE:AE,$AK13)="","",INDEX(LookupData!AE:AE,$AK13)))) | AF13: =IF($AK13="","",IF($AK13=0,"",IF(INDEX(LookupData!AF:AF,$AK13)="","",INDEX(LookupData!AF:AF,$AK13)))) | AG13: =IF($AK13="","",IF($AK13=0,"",IF(INDEX(LookupData!AG:AG,$AK13)="","",INDEX(LookupData!AG:AG,$AK13)))) | AH13: =IF($AK13="","",IF($AK13=0,"",IF(INDEX(LookupData!AH:AH,$AK13)="","",INDEX(LookupData!AH:AH,$AK13)))) | AI13: =IF($AK13="","",IF($AK13=0,"",IF(INDEX(LookupData!AI:AI,$AK13)="","",HYPERLINK(INDEX(LookupData!AI:AI,$AK13),"Open")))) | AK13: =IF(AL13="","",IFERROR(MATCH(AL13,LookupData!$A:$A,0),0)) | AL13: =IF(TRIM($A13)="","",UPPER(TRIM($A13))) | AM13: =IF(AL13="",AM12,IF(AM12="",AL13,AM12&"|"&AL13)) | AO13: =IF(MID($AN$1,2881,240)="","|",MID($AN$1,2881,240)) -> |
B14: =IF($AK14="","",IF($AK14=0,"not in the database",IF(INDEX(LookupData!B:B,$AK14)="","",INDEX(LookupData!B:B,$AK14)))) | C14: =IF($AK14="","",IF($AK14=0,"",IF(INDEX(LookupData!C:C,$AK14)="","",INDEX(LookupData!C:C,$AK14)))) | D14: =IF($AK14="","",IF($AK14=0,"",IF(INDEX(LookupData!D:D,$AK14)="","",INDEX(LookupData!D:D,$AK14)))) | E14: =IF($AK14="","",IF($AK14=0,"",IF(INDEX(LookupData!E:E,$AK14)="","",INDEX(LookupData!E:E,$AK14)))) | F14: =IF($AK14="","",IF($AK14=0,"",IF(INDEX(LookupData!F:F,$AK14)="","",INDEX(LookupData!F:F,$AK14)))) | G14: =IF($AK14="","",IF($AK14=0,"",IF(INDEX(LookupData!G:G,$AK14)="","",INDEX(LookupData!G:G,$AK14)))) | H14: =IF($AK14="","",IF($AK14=0,"",IF(INDEX(LookupData!H:H,$AK14)="","",INDEX(LookupData!H:H,$AK14)))) | I14: =IF($AK14="","",IF($AK14=0,"",IF(INDEX(LookupData!I:I,$AK14)="","",INDEX(LookupData!I:I,$AK14)))) | J14: =IF($AK14="","",IF($AK14=0,"",IF(INDEX(LookupData!J:J,$AK14)="","",INDEX(LookupData!J:J,$AK14)))) | K14: =IF($AK14="","",IF($AK14=0,"",IF(INDEX(LookupData!K:K,$AK14)="","",INDEX(LookupData!K:K,$AK14)))) | L14: =IF($AK14="","",IF($AK14=0,"",IF(INDEX(LookupData!L:L,$AK14)="","",INDEX(LookupData!L:L,$AK14)))) | M14: =IF($AK14="","",IF($AK14=0,"",IF(INDEX(LookupData!M:M,$AK14)="","",INDEX(LookupData!M:M,$AK14)))) | N14: =IF($AK14="","",IF($AK14=0,"",IF(INDEX(LookupData!N:N,$AK14)="","",INDEX(LookupData!N:N,$AK14)))) | O14: =IF($AK14="","",IF($AK14=0,"",IF(INDEX(LookupData!O:O,$AK14)="","",INDEX(LookupData!O:O,$AK14)))) | P14: =IF($AK14="","",IF($AK14=0,"",IF(INDEX(LookupData!P:P,$AK14)="","",INDEX(LookupData!P:P,$AK14)))) | Q14: =IF($AK14="","",IF($AK14=0,"",IF(INDEX(LookupData!Q:Q,$AK14)="","",INDEX(LookupData!Q:Q,$AK14)))) | R14: =IF($AK14="","",IF($AK14=0,"",IF(INDEX(LookupData!R:R,$AK14)="","",INDEX(LookupData!R:R,$AK14)))) | S14: =IF($AK14="","",IF($AK14=0,"",IF(INDEX(LookupData!S:S,$AK14)="","",INDEX(LookupData!S:S,$AK14)))) | T14: =IF($AK14="","",IF($AK14=0,"",IF(INDEX(LookupData!T:T,$AK14)="","",INDEX(LookupData!T:T,$AK14)))) | U14: =IF($AK14="","",IF($AK14=0,"",IF(INDEX(LookupData!U:U,$AK14)="","",INDEX(LookupData!U:U,$AK14)))) | V14: =IF($AK14="","",IF($AK14=0,"",IF(INDEX(LookupData!V:V,$AK14)="","",INDEX(LookupData!V:V,$AK14)))) | W14: =IF($AK14="","",IF($AK14=0,"",IF(INDEX(LookupData!W:W,$AK14)="","",INDEX(LookupData!W:W,$AK14)))) | X14: =IF($AK14="","",IF($AK14=0,"",IF(INDEX(LookupData!X:X,$AK14)="","",INDEX(LookupData!X:X,$AK14)))) | Y14: =IF($AK14="","",IF($AK14=0,"",IF(INDEX(LookupData!Y:Y,$AK14)="","",INDEX(LookupData!Y:Y,$AK14)))) | Z14: =IF($AK14="","",IF($AK14=0,"",IF(INDEX(LookupData!Z:Z,$AK14)="","",INDEX(LookupData!Z:Z,$AK14)))) | AA14: =IF($AK14="","",IF($AK14=0,"",IF(INDEX(LookupData!AA:AA,$AK14)="","",INDEX(LookupData!AA:AA,$AK14)))) | AB14: =IF($AK14="","",IF($AK14=0,"",IF(INDEX(LookupData!AB:AB,$AK14)="","",INDEX(LookupData!AB:AB,$AK14)))) | AC14: =IF($AK14="","",IF($AK14=0,"",IF(INDEX(LookupData!AC:AC,$AK14)="","",INDEX(LookupData!AC:AC,$AK14)))) | AD14: =IF($AK14="","",IF($AK14=0,"",IF(INDEX(LookupData!AD:AD,$AK14)="","",INDEX(LookupData!AD:AD,$AK14)))) | AE14: =IF($AK14="","",IF($AK14=0,"",IF(INDEX(LookupData!AE:AE,$AK14)="","",INDEX(LookupData!AE:AE,$AK14)))) | AF14: =IF($AK14="","",IF($AK14=0,"",IF(INDEX(LookupData!AF:AF,$AK14)="","",INDEX(LookupData!AF:AF,$AK14)))) | AG14: =IF($AK14="","",IF($AK14=0,"",IF(INDEX(LookupData!AG:AG,$AK14)="","",INDEX(LookupData!AG:AG,$AK14)))) | AH14: =IF($AK14="","",IF($AK14=0,"",IF(INDEX(LookupData!AH:AH,$AK14)="","",INDEX(LookupData!AH:AH,$AK14)))) | AI14: =IF($AK14="","",IF($AK14=0,"",IF(INDEX(LookupData!AI:AI,$AK14)="","",HYPERLINK(INDEX(LookupData!AI:AI,$AK14),"Open")))) | AK14: =IF(AL14="","",IFERROR(MATCH(AL14,LookupData!$A:$A,0),0)) | AL14: =IF(TRIM($A14)="","",UPPER(TRIM($A14))) | AM14: =IF(AL14="",AM13,IF(AM13="",AL14,AM13&"|"&AL14)) | AO14: =IF(MID($AN$1,3121,240)="","|",MID($AN$1,3121,240)) -> |
B15: =IF($AK15="","",IF($AK15=0,"not in the database",IF(INDEX(LookupData!B:B,$AK15)="","",INDEX(LookupData!B:B,$AK15)))) | C15: =IF($AK15="","",IF($AK15=0,"",IF(INDEX(LookupData!C:C,$AK15)="","",INDEX(LookupData!C:C,$AK15)))) | D15: =IF($AK15="","",IF($AK15=0,"",IF(INDEX(LookupData!D:D,$AK15)="","",INDEX(LookupData!D:D,$AK15)))) | E15: =IF($AK15="","",IF($AK15=0,"",IF(INDEX(LookupData!E:E,$AK15)="","",INDEX(LookupData!E:E,$AK15)))) | F15: =IF($AK15="","",IF($AK15=0,"",IF(INDEX(LookupData!F:F,$AK15)="","",INDEX(LookupData!F:F,$AK15)))) | G15: =IF($AK15="","",IF($AK15=0,"",IF(INDEX(LookupData!G:G,$AK15)="","",INDEX(LookupData!G:G,$AK15)))) | H15: =IF($AK15="","",IF($AK15=0,"",IF(INDEX(LookupData!H:H,$AK15)="","",INDEX(LookupData!H:H,$AK15)))) | I15: =IF($AK15="","",IF($AK15=0,"",IF(INDEX(LookupData!I:I,$AK15)="","",INDEX(LookupData!I:I,$AK15)))) | J15: =IF($AK15="","",IF($AK15=0,"",IF(INDEX(LookupData!J:J,$AK15)="","",INDEX(LookupData!J:J,$AK15)))) | K15: =IF($AK15="","",IF($AK15=0,"",IF(INDEX(LookupData!K:K,$AK15)="","",INDEX(LookupData!K:K,$AK15)))) | L15: =IF($AK15="","",IF($AK15=0,"",IF(INDEX(LookupData!L:L,$AK15)="","",INDEX(LookupData!L:L,$AK15)))) | M15: =IF($AK15="","",IF($AK15=0,"",IF(INDEX(LookupData!M:M,$AK15)="","",INDEX(LookupData!M:M,$AK15)))) | N15: =IF($AK15="","",IF($AK15=0,"",IF(INDEX(LookupData!N:N,$AK15)="","",INDEX(LookupData!N:N,$AK15)))) | O15: =IF($AK15="","",IF($AK15=0,"",IF(INDEX(LookupData!O:O,$AK15)="","",INDEX(LookupData!O:O,$AK15)))) | P15: =IF($AK15="","",IF($AK15=0,"",IF(INDEX(LookupData!P:P,$AK15)="","",INDEX(LookupData!P:P,$AK15)))) | Q15: =IF($AK15="","",IF($AK15=0,"",IF(INDEX(LookupData!Q:Q,$AK15)="","",INDEX(LookupData!Q:Q,$AK15)))) | R15: =IF($AK15="","",IF($AK15=0,"",IF(INDEX(LookupData!R:R,$AK15)="","",INDEX(LookupData!R:R,$AK15)))) | S15: =IF($AK15="","",IF($AK15=0,"",IF(INDEX(LookupData!S:S,$AK15)="","",INDEX(LookupData!S:S,$AK15)))) | T15: =IF($AK15="","",IF($AK15=0,"",IF(INDEX(LookupData!T:T,$AK15)="","",INDEX(LookupData!T:T,$AK15)))) | U15: =IF($AK15="","",IF($AK15=0,"",IF(INDEX(LookupData!U:U,$AK15)="","",INDEX(LookupData!U:U,$AK15)))) | V15: =IF($AK15="","",IF($AK15=0,"",IF(INDEX(LookupData!V:V,$AK15)="","",INDEX(LookupData!V:V,$AK15)))) | W15: =IF($AK15="","",IF($AK15=0,"",IF(INDEX(LookupData!W:W,$AK15)="","",INDEX(LookupData!W:W,$AK15)))) | X15: =IF($AK15="","",IF($AK15=0,"",IF(INDEX(LookupData!X:X,$AK15)="","",INDEX(LookupData!X:X,$AK15)))) | Y15: =IF($AK15="","",IF($AK15=0,"",IF(INDEX(LookupData!Y:Y,$AK15)="","",INDEX(LookupData!Y:Y,$AK15)))) | Z15: =IF($AK15="","",IF($AK15=0,"",IF(INDEX(LookupData!Z:Z,$AK15)="","",INDEX(LookupData!Z:Z,$AK15)))) | AA15: =IF($AK15="","",IF($AK15=0,"",IF(INDEX(LookupData!AA:AA,$AK15)="","",INDEX(LookupData!AA:AA,$AK15)))) | AB15: =IF($AK15="","",IF($AK15=0,"",IF(INDEX(LookupData!AB:AB,$AK15)="","",INDEX(LookupData!AB:AB,$AK15)))) | AC15: =IF($AK15="","",IF($AK15=0,"",IF(INDEX(LookupData!AC:AC,$AK15)="","",INDEX(LookupData!AC:AC,$AK15)))) | AD15: =IF($AK15="","",IF($AK15=0,"",IF(INDEX(LookupData!AD:AD,$AK15)="","",INDEX(LookupData!AD:AD,$AK15)))) | AE15: =IF($AK15="","",IF($AK15=0,"",IF(INDEX(LookupData!AE:AE,$AK15)="","",INDEX(LookupData!AE:AE,$AK15)))) | AF15: =IF($AK15="","",IF($AK15=0,"",IF(INDEX(LookupData!AF:AF,$AK15)="","",INDEX(LookupData!AF:AF,$AK15)))) | AG15: =IF($AK15="","",IF($AK15=0,"",IF(INDEX(LookupData!AG:AG,$AK15)="","",INDEX(LookupData!AG:AG,$AK15)))) | AH15: =IF($AK15="","",IF($AK15=0,"",IF(INDEX(LookupData!AH:AH,$AK15)="","",INDEX(LookupData!AH:AH,$AK15)))) | AI15: =IF($AK15="","",IF($AK15=0,"",IF(INDEX(LookupData!AI:AI,$AK15)="","",HYPERLINK(INDEX(LookupData!AI:AI,$AK15),"Open")))) | AK15: =IF(AL15="","",IFERROR(MATCH(AL15,LookupData!$A:$A,0),0)) | AL15: =IF(TRIM($A15)="","",UPPER(TRIM($A15))) | AM15: =IF(AL15="",AM14,IF(AM14="",AL15,AM14&"|"&AL15)) | AO15: =IF(MID($AN$1,3361,240)="","|",MID($AN$1,3361,240)) -> |
B16: =IF($AK16="","",IF($AK16=0,"not in the database",IF(INDEX(LookupData!B:B,$AK16)="","",INDEX(LookupData!B:B,$AK16)))) | C16: =IF($AK16="","",IF($AK16=0,"",IF(INDEX(LookupData!C:C,$AK16)="","",INDEX(LookupData!C:C,$AK16)))) | D16: =IF($AK16="","",IF($AK16=0,"",IF(INDEX(LookupData!D:D,$AK16)="","",INDEX(LookupData!D:D,$AK16)))) | E16: =IF($AK16="","",IF($AK16=0,"",IF(INDEX(LookupData!E:E,$AK16)="","",INDEX(LookupData!E:E,$AK16)))) | F16: =IF($AK16="","",IF($AK16=0,"",IF(INDEX(LookupData!F:F,$AK16)="","",INDEX(LookupData!F:F,$AK16)))) | G16: =IF($AK16="","",IF($AK16=0,"",IF(INDEX(LookupData!G:G,$AK16)="","",INDEX(LookupData!G:G,$AK16)))) | H16: =IF($AK16="","",IF($AK16=0,"",IF(INDEX(LookupData!H:H,$AK16)="","",INDEX(LookupData!H:H,$AK16)))) | I16: =IF($AK16="","",IF($AK16=0,"",IF(INDEX(LookupData!I:I,$AK16)="","",INDEX(LookupData!I:I,$AK16)))) | J16: =IF($AK16="","",IF($AK16=0,"",IF(INDEX(LookupData!J:J,$AK16)="","",INDEX(LookupData!J:J,$AK16)))) | K16: =IF($AK16="","",IF($AK16=0,"",IF(INDEX(LookupData!K:K,$AK16)="","",INDEX(LookupData!K:K,$AK16)))) | L16: =IF($AK16="","",IF($AK16=0,"",IF(INDEX(LookupData!L:L,$AK16)="","",INDEX(LookupData!L:L,$AK16)))) | M16: =IF($AK16="","",IF($AK16=0,"",IF(INDEX(LookupData!M:M,$AK16)="","",INDEX(LookupData!M:M,$AK16)))) | N16: =IF($AK16="","",IF($AK16=0,"",IF(INDEX(LookupData!N:N,$AK16)="","",INDEX(LookupData!N:N,$AK16)))) | O16: =IF($AK16="","",IF($AK16=0,"",IF(INDEX(LookupData!O:O,$AK16)="","",INDEX(LookupData!O:O,$AK16)))) | P16: =IF($AK16="","",IF($AK16=0,"",IF(INDEX(LookupData!P:P,$AK16)="","",INDEX(LookupData!P:P,$AK16)))) | Q16: =IF($AK16="","",IF($AK16=0,"",IF(INDEX(LookupData!Q:Q,$AK16)="","",INDEX(LookupData!Q:Q,$AK16)))) | R16: =IF($AK16="","",IF($AK16=0,"",IF(INDEX(LookupData!R:R,$AK16)="","",INDEX(LookupData!R:R,$AK16)))) | S16: =IF($AK16="","",IF($AK16=0,"",IF(INDEX(LookupData!S:S,$AK16)="","",INDEX(LookupData!S:S,$AK16)))) | T16: =IF($AK16="","",IF($AK16=0,"",IF(INDEX(LookupData!T:T,$AK16)="","",INDEX(LookupData!T:T,$AK16)))) | U16: =IF($AK16="","",IF($AK16=0,"",IF(INDEX(LookupData!U:U,$AK16)="","",INDEX(LookupData!U:U,$AK16)))) | V16: =IF($AK16="","",IF($AK16=0,"",IF(INDEX(LookupData!V:V,$AK16)="","",INDEX(LookupData!V:V,$AK16)))) | W16: =IF($AK16="","",IF($AK16=0,"",IF(INDEX(LookupData!W:W,$AK16)="","",INDEX(LookupData!W:W,$AK16)))) | X16: =IF($AK16="","",IF($AK16=0,"",IF(INDEX(LookupData!X:X,$AK16)="","",INDEX(LookupData!X:X,$AK16)))) | Y16: =IF($AK16="","",IF($AK16=0,"",IF(INDEX(LookupData!Y:Y,$AK16)="","",INDEX(LookupData!Y:Y,$AK16)))) | Z16: =IF($AK16="","",IF($AK16=0,"",IF(INDEX(LookupData!Z:Z,$AK16)="","",INDEX(LookupData!Z:Z,$AK16)))) | AA16: =IF($AK16="","",IF($AK16=0,"",IF(INDEX(LookupData!AA:AA,$AK16)="","",INDEX(LookupData!AA:AA,$AK16)))) | AB16: =IF($AK16="","",IF($AK16=0,"",IF(INDEX(LookupData!AB:AB,$AK16)="","",INDEX(LookupData!AB:AB,$AK16)))) | AC16: =IF($AK16="","",IF($AK16=0,"",IF(INDEX(LookupData!AC:AC,$AK16)="","",INDEX(LookupData!AC:AC,$AK16)))) | AD16: =IF($AK16="","",IF($AK16=0,"",IF(INDEX(LookupData!AD:AD,$AK16)="","",INDEX(LookupData!AD:AD,$AK16)))) | AE16: =IF($AK16="","",IF($AK16=0,"",IF(INDEX(LookupData!AE:AE,$AK16)="","",INDEX(LookupData!AE:AE,$AK16)))) | AF16: =IF($AK16="","",IF($AK16=0,"",IF(INDEX(LookupData!AF:AF,$AK16)="","",INDEX(LookupData!AF:AF,$AK16)))) | AG16: =IF($AK16="","",IF($AK16=0,"",IF(INDEX(LookupData!AG:AG,$AK16)="","",INDEX(LookupData!AG:AG,$AK16)))) | AH16: =IF($AK16="","",IF($AK16=0,"",IF(INDEX(LookupData!AH:AH,$AK16)="","",INDEX(LookupData!AH:AH,$AK16)))) | AI16: =IF($AK16="","",IF($AK16=0,"",IF(INDEX(LookupData!AI:AI,$AK16)="","",HYPERLINK(INDEX(LookupData!AI:AI,$AK16),"Open")))) | AK16: =IF(AL16="","",IFERROR(MATCH(AL16,LookupData!$A:$A,0),0)) | AL16: =IF(TRIM($A16)="","",UPPER(TRIM($A16))) | AM16: =IF(AL16="",AM15,IF(AM15="",AL16,AM15&"|"&AL16)) | AO16: =IF(MID($AN$1,3601,240)="","|",MID($AN$1,3601,240)) -> |
